<mujoco model="stanford_quadruped_fixed">
  <compiler angle="radian" autolimits="true"/>
  <option timestep="0.001000" integrator="RK4" gravity="0 0 -9.81"/>
  <visual>
    <headlight ambient="0.35 0.35 0.35" diffuse="0.75 0.75 0.75" specular="0.20 0.20 0.20"/>
    <map znear="0.01"/>
  </visual>
  <asset>
    <texture name="grid" type="2d" builtin="checker" rgb1="0.20 0.20 0.20" rgb2="0.10 0.10 0.10" width="512" height="512"/>
    <material name="grid" texture="grid" texrepeat="4 4" reflectance="0.15"/>
  </asset>
  <worldbody>
    <light name="sun" pos="0 0 1.8" dir="0 0 -1" directional="true"/>
    <geom name="floor" type="plane" size="3 3 0.1" material="grid" friction="1.500 0.05 0.01"/>
    <camera name="overview" pos="0.70 -1.10 0.55" xyaxes="1.0 0.0 0.0 0.0 0.6 0.8"/>
    <body name="torso" pos="0 0 0.300000">
      <geom name="torso_geom" type="box" size="0.138000 0.050000 0.025000" rgba="0.18 0.18 0.18 1"/>
      <site name="torso_center" pos="0 0 0" size="0.01" rgba="1 1 1 1"/>

    <body name="fr_abad_body" pos="0.100000 -0.040000 0.000000">
      <joint name="fr_abad" type="hinge" axis="1 0 0" range="-1.4 1.4" damping="1.049000" armature="0.019360"/>
      <geom name="fr_abad_link" type="capsule" fromto="0 0 0 0 -0.030000 0" size="0.009" rgba="0.90 0.30 0.30 1"/>
      <body name="fr_hip_body" pos="0 -0.030000 0">
        <joint name="fr_hip" type="hinge" axis="0 1 0" range="-2.5 2.5" damping="1.049000" armature="0.019360"/>
        <geom name="fr_upper_link" type="capsule" fromto="0 0 0 0 0 -0.123500" size="0.008" rgba="0.90 0.30 0.30 1"/>
        <body name="fr_knee_body" pos="0 0 -0.123500">
          <joint name="fr_knee" type="hinge" axis="0 1 0" range="-2.8 0.4" damping="1.049000" armature="0.019360"/>
          <geom name="fr_lower_link" type="capsule" fromto="0 0 0 0 0 -0.115000" size="0.007" rgba="0.90 0.30 0.30 1"/>
          <geom name="fr_foot_geom" type="sphere" pos="0 0 -0.115000" size="0.010000" rgba="0.90 0.30 0.30 1"/>
          <site name="fr_foot" pos="0 0 -0.115000" size="0.012" rgba="0.90 0.30 0.30 1"/>
        </body>
      </body>
    </body>
    

    <body name="fl_abad_body" pos="0.100000 0.040000 0.000000">
      <joint name="fl_abad" type="hinge" axis="1 0 0" range="-1.4 1.4" damping="1.049000" armature="0.019360"/>
      <geom name="fl_abad_link" type="capsule" fromto="0 0 0 0 0.030000 0" size="0.009" rgba="0.30 0.90 0.30 1"/>
      <body name="fl_hip_body" pos="0 0.030000 0">
        <joint name="fl_hip" type="hinge" axis="0 1 0" range="-2.5 2.5" damping="1.049000" armature="0.019360"/>
        <geom name="fl_upper_link" type="capsule" fromto="0 0 0 0 0 -0.123500" size="0.008" rgba="0.30 0.90 0.30 1"/>
        <body name="fl_knee_body" pos="0 0 -0.123500">
          <joint name="fl_knee" type="hinge" axis="0 1 0" range="-2.8 0.4" damping="1.049000" armature="0.019360"/>
          <geom name="fl_lower_link" type="capsule" fromto="0 0 0 0 0 -0.115000" size="0.007" rgba="0.30 0.90 0.30 1"/>
          <geom name="fl_foot_geom" type="sphere" pos="0 0 -0.115000" size="0.010000" rgba="0.30 0.90 0.30 1"/>
          <site name="fl_foot" pos="0 0 -0.115000" size="0.012" rgba="0.30 0.90 0.30 1"/>
        </body>
      </body>
    </body>
    

    <body name="br_abad_body" pos="-0.100000 -0.040000 0.000000">
      <joint name="br_abad" type="hinge" axis="1 0 0" range="-1.4 1.4" damping="1.049000" armature="0.019360"/>
      <geom name="br_abad_link" type="capsule" fromto="0 0 0 0 -0.030000 0" size="0.009" rgba="0.30 0.30 0.90 1"/>
      <body name="br_hip_body" pos="0 -0.030000 0">
        <joint name="br_hip" type="hinge" axis="0 1 0" range="-2.5 2.5" damping="1.049000" armature="0.019360"/>
        <geom name="br_upper_link" type="capsule" fromto="0 0 0 0 0 -0.123500" size="0.008" rgba="0.30 0.30 0.90 1"/>
        <body name="br_knee_body" pos="0 0 -0.123500">
          <joint name="br_knee" type="hinge" axis="0 1 0" range="-2.8 0.4" damping="1.049000" armature="0.019360"/>
          <geom name="br_lower_link" type="capsule" fromto="0 0 0 0 0 -0.115000" size="0.007" rgba="0.30 0.30 0.90 1"/>
          <geom name="br_foot_geom" type="sphere" pos="0 0 -0.115000" size="0.010000" rgba="0.30 0.30 0.90 1"/>
          <site name="br_foot" pos="0 0 -0.115000" size="0.012" rgba="0.30 0.30 0.90 1"/>
        </body>
      </body>
    </body>
    

    <body name="bl_abad_body" pos="-0.100000 0.040000 0.000000">
      <joint name="bl_abad" type="hinge" axis="1 0 0" range="-1.4 1.4" damping="1.049000" armature="0.019360"/>
      <geom name="bl_abad_link" type="capsule" fromto="0 0 0 0 0.030000 0" size="0.009" rgba="0.90 0.90 0.30 1"/>
      <body name="bl_hip_body" pos="0 0.030000 0">
        <joint name="bl_hip" type="hinge" axis="0 1 0" range="-2.5 2.5" damping="1.049000" armature="0.019360"/>
        <geom name="bl_upper_link" type="capsule" fromto="0 0 0 0 0 -0.123500" size="0.008" rgba="0.90 0.90 0.30 1"/>
        <body name="bl_knee_body" pos="0 0 -0.123500">
          <joint name="bl_knee" type="hinge" axis="0 1 0" range="-2.8 0.4" damping="1.049000" armature="0.019360"/>
          <geom name="bl_lower_link" type="capsule" fromto="0 0 0 0 0 -0.115000" size="0.007" rgba="0.90 0.90 0.30 1"/>
          <geom name="bl_foot_geom" type="sphere" pos="0 0 -0.115000" size="0.010000" rgba="0.90 0.90 0.30 1"/>
          <site name="bl_foot" pos="0 0 -0.115000" size="0.012" rgba="0.90 0.90 0.30 1"/>
        </body>
      </body>
    </body>
    
    </body>
  </worldbody>
</mujoco>
